Workbook
Name Slicer_Date_Hierarchy1: #N/A
Name Slicer_geolocation_state: #N/A
Name Slicer_payment_type: #N/A
Name Slicer_Reconciliation_Status: #N/A

Sheet Dashboard_Data
A1: Dashboard Data — LINK YOUR MODEL HERE | B1: Dashboard Data — LINK YOUR MODEL HERE | C1: Dashboard Data — LINK YOUR MODEL HERE | D1: Dashboard Data — LINK YOUR MODEL HERE | E1: Dashboard Data — LINK YOUR MODEL HERE | F1: Dashboard Data — LINK YOUR MODEL HERE | G1: Dashboard Data — LINK YOUR MODEL HERE | H1: Dashboard Data — LINK YOUR MODEL HERE | I1: Dashboard Data — LINK YOUR MODEL HERE | O1: Dashboard Data — LINK YOUR MODEL HERE | P1: Dashboard Data — LINK YOUR MODEL HERE | Q1: Dashboard Data — LINK YOUR MODEL HERE | R1: Dashboard Data — LINK YOUR MODEL HERE | S1: Dashboard Data — LINK YOUR MODEL HERE
A2: Dashboard Data — LINK YOUR MODEL HERE | B2: Dashboard Data — LINK YOUR MODEL HERE | C2: Dashboard Data — LINK YOUR MODEL HERE | D2: Dashboard Data — LINK YOUR MODEL HERE | E2: Dashboard Data — LINK YOUR MODEL HERE | F2: Dashboard Data — LINK YOUR MODEL HERE | G2: Dashboard Data — LINK YOUR MODEL HERE | H2: Dashboard Data — LINK YOUR MODEL HERE | I2: Dashboard Data — LINK YOUR MODEL HERE | O2: Dashboard Data — LINK YOUR MODEL HERE | P2: Dashboard Data — LINK YOUR MODEL HERE | Q2: Dashboard Data — LINK YOUR MODEL HERE | R2: Dashboard Data — LINK YOUR MODEL HERE | S2: Dashboard Data — LINK YOUR MODEL HERE
A3: Blank by design: connect your measures / Pivot outputs / Power Query results later. | B3: Blank by design: connect your measures / Pivot outputs / Power Query results later. | C3: Blank by design: connect your measures / Pivot outputs / Power Query results later. | D3: Blank by design: connect your measures / Pivot outputs / Power Query results later. | E3: Blank by design: connect your measures / Pivot outputs / Power Query results later. | F3: Blank by design: connect your measures / Pivot outputs / Power Query results later. | G3: Blank by design: connect your measures / Pivot outputs / Power Query results later. | H3: Blank by design: connect your measures / Pivot outputs / Power Query results later. | I3: Blank by design: connect your measures / Pivot outputs / Power Query results later. | O3: Blank by design: connect your measures / Pivot outputs / Power Query results later. | P3: Blank by design: connect your measures / Pivot outputs / Power Query results later. | Q3: Blank by design: connect your measures / Pivot outputs / Power Query results later. | R3: Blank by design: connect your measures / Pivot outputs / Power Query results later. | S3: Blank by design: connect your measures / Pivot outputs / Power Query results later.
A5: KPI | B5: Value | C5: Format | E5: Year | F5: Total Sales | G5: Total Freight | H5: Order Value | I5: Orders | P5: Year | Q5: Total Sales | R5: Total Customers | S5: Customers
A6: Total Sales | B6: =B25 -> 13591644 | C6: =F9 -> 0 | E6: 2016 | F6: 49785.92 | G6: 7397.29 | H6: =F6+G6 -> 57183.21 | P6: May | Q6: 1502588.8 | R6: 10573
A7: Total Orders | B7: =C25 -> 99441 | C7: =H9 -> 15843553 | E7: 2017 | F7: 6155807 | G7: 986865.45 | H7: =F7+G7 -> 7142672.4 | P7: August | Q7: 1428658 | R7: 10843
A8: Average Order Value | B8: =D25 -> 159.32617 | C8: currency2 | E8: 2018 | F8: 7386050.8 | G8: 1257646.8 | H8: =F8+G8 -> 8643697.6 | P8: July | Q8: 1393538.7 | R8: 10318
A9: Total Customers | B9: =E25 -> 99441 | C9: integer | H9: =SUM(H6:H8) -> 15843553 | P9: March | Q9: 1357557.7 | R9: 9893
A10: Total Products | B10: =F25 -> 112650 | C10: integer | P10: April | Q10: 1356575 | R10: 9343
A11: Total Sellers | B11: =G25 -> 3095 | C11: integer | P11: June | Q11: 1298162.9 | R11: 9412
A12: Average Review Score | B12: =H25 -> 4.0864206 | C12: score | P12: February | Q12: 1091481.7 | R12: 8508
A13: Average Delivery Days | B13: =I25 -> 12.497336 | C13: days | P13: January | Q13: 1070343.2 | R13: 8069
A14: On-Time Delivery % | B14: =J25 -> 0.93226295 | C14: percent | P14: November | Q14: 1010271.4 | R14: 7544
A15: Late Orders | B15: =K25 -> 6535 | C15: integer | P15: December | Q15: 743925.07 | R15: 5674
A16: Not Delivered | B16: =L25 -> 2965 | C16: integer | P16: October | Q16: 713727.09 | R16: 4959
P17: September | Q17: 624814.05 | R17: 4305
P18: Grand Total | Q18: 13591644 | R18: 99441
A19: Row Labels | B19: Total Sales | C19: Total Orders | D19: Average Order Value | E19: Total Customers | F19: Total Products Sold | G19: Total Seller | H19: Average Review Score | I19: Average Delivery Days | J19: On-Time Delivery % | K19: Late Orders | L19: Not Delivered | M19: Top Category
A20: 2016 | B20: 49785.92 | C20: 329 | D20: 173.80915 | E20: 329 | F20: 370 | G20: 145 | H20: 3.5429448 | I20: 19.6875 | J20: 0.98897059 | K20: 3 | L20: 57 | M20: moveis_decoracao
A21: 2017 | B21: 6155807 | C21: 45101 | D21: 158.3706 | E21: 45101 | F21: 50864 | G21: 1784 | H21: 4.0872702 | I21: 12.979045 | J21: 0.9435131 | K21: 2453 | L21: 1675 | M21: cama_mesa_banho
A22: 2018 | B22: 7386050.8 | C22: 54011 | D22: 160.03587 | E22: 54011 | F22: 61416 | G22: 2383 | H22: 4.0889999 | I22: 12.063928 | J22: 0.92271401 | K22: 4079 | L22: 1233 | M22: beleza_saude
A23: 2019
A24: 2020
A25: Grand Total | B25: 13591644 | C25: 99441 | D25: 159.32617 | E25: 99441 | F25: 112650 | G25: 3095 | H25: 4.0864206 | I25: 12.497336 | J25: 0.93226295 | K25: 6535 | L25: 2965 | M25: beleza_saude
A71: Category | B71: Sales | D71: Product | H71: Sales | O71: Payment Type | P71: Payment Value | R71: Delivery Status | S71: Total Orders
A72: Category 1 | D72: Product 1 | G72: Seller 1 | O72: debit_card | P72: 217989.79 | R72: Late | S72: 6535
A73: Category 2 | D73: Product 2 | G73: Seller 2 | O73: Grand Total | P73: 217989.79 | R73: Not Delivered | S73: 2965
A74: Category 3 | D74: Product 3 | G74: Seller 3 | R74: On Time | S74: 89941
A75: Category 4 | D75: Product 4 | G75: Seller 4 | R75: Grand Total | S75: 99441
A76: Category 5 | D76: Product 5 | G76: Seller 5
A77: Category 6 | D77: Product 6 | G77: Seller 6
A78: Category 7 | D78: Product 7 | G78: Seller 7
A79: Category 8 | D79: Product 8 | G79: Seller 8
A80: Category 9 | D80: Product 9 | G80: Seller 9
A81: Category 10 | D81: Product 10 | G81: Seller 10
A84: Review Score | B84: %review_score | D84: State | E84: Customers | G84: Installments | H84: Payment Value | O84: LINKING NOTE Replace the blank cells on this sheet with your Power Pivot measures, Pivot outputs, CUBE formulas, or Power Query results. The four dashboard pages already reference these cells/ranges. | P84: LINKING NOTE Replace the blank cells on this sheet with your Power Pivot measures, Pivot outputs, CUBE formulas, or Power Query results. The four dashboard pages already reference these cells/ranges. | Q84: LINKING NOTE Replace the blank cells on this sheet with your Power Pivot measures, Pivot outputs, CUBE formulas, or Power Query results. The four dashboard pages already reference these cells/ranges. | R84: LINKING NOTE Replace the blank cells on this sheet with your Power Pivot measures, Pivot outputs, CUBE formulas, or Power Query results. The four dashboard pages already reference these cells/ranges. | S84: LINKING NOTE Replace the blank cells on this sheet with your Power Pivot measures, Pivot outputs, CUBE formulas, or Power Query results. The four dashboard pages already reference these cells/ranges.
A85: 1 | B85: 0.11513344 | D85: State 1 | G85: 1 | O85: LINKING NOTE Replace the blank cells on this sheet with your Power Pivot measures, Pivot outputs, CUBE formulas, or Power Query results. The four dashboard pages already reference these cells/ranges. | P85: LINKING NOTE Replace the blank cells on this sheet with your Power Pivot measures, Pivot outputs, CUBE formulas, or Power Query results. The four dashboard pages already reference these cells/ranges. | Q85: LINKING NOTE Replace the blank cells on this sheet with your Power Pivot measures, Pivot outputs, CUBE formulas, or Power Query results. The four dashboard pages already reference these cells/ranges. | R85: LINKING NOTE Replace the blank cells on this sheet with your Power Pivot measures, Pivot outputs, CUBE formulas, or Power Query results. The four dashboard pages already reference these cells/ranges. | S85: LINKING NOTE Replace the blank cells on this sheet with your Power Pivot measures, Pivot outputs, CUBE formulas, or Power Query results. The four dashboard pages already reference these cells/ranges.
A86: 2 | B86: 0.03175643 | D86: State 2 | G86: 2 | O86: LINKING NOTE Replace the blank cells on this sheet with your Power Pivot measures, Pivot outputs, CUBE formulas, or Power Query results. The four dashboard pages already reference these cells/ranges. | P86: LINKING NOTE Replace the blank cells on this sheet with your Power Pivot measures, Pivot outputs, CUBE formulas, or Power Query results. The four dashboard pages already reference these cells/ranges. | Q86: LINKING NOTE Replace the blank cells on this sheet with your Power Pivot measures, Pivot outputs, CUBE formulas, or Power Query results. The four dashboard pages already reference these cells/ranges. | R86: LINKING NOTE Replace the blank cells on this sheet with your Power Pivot measures, Pivot outputs, CUBE formulas, or Power Query results. The four dashboard pages already reference these cells/ranges. | S86: LINKING NOTE Replace the blank cells on this sheet with your Power Pivot measures, Pivot outputs, CUBE formulas, or Power Query results. The four dashboard pages already reference these cells/ranges.
A87: 3 | B87: 0.082429654 | D87: State 3 | G87: 3 | O87: LINKING NOTE Replace the blank cells on this sheet with your Power Pivot measures, Pivot outputs, CUBE formulas, or Power Query results. The four dashboard pages already reference these cells/ranges. | P87: LINKING NOTE Replace the blank cells on this sheet with your Power Pivot measures, Pivot outputs, CUBE formulas, or Power Query results. The four dashboard pages already reference these cells/ranges. | Q87: LINKING NOTE Replace the blank cells on this sheet with your Power Pivot measures, Pivot outputs, CUBE formulas, or Power Query results. The four dashboard pages already reference these cells/ranges. | R87: LINKING NOTE Replace the blank cells on this sheet with your Power Pivot measures, Pivot outputs, CUBE formulas, or Power Query results. The four dashboard pages already reference these cells/ranges. | S87: LINKING NOTE Replace the blank cells on this sheet with your Power Pivot measures, Pivot outputs, CUBE formulas, or Power Query results. The four dashboard pages already reference these cells/ranges.
A88: 4 | B88: 0.19291704 | D88: State 4 | G88: 4 | O88: LINKING NOTE Replace the blank cells on this sheet with your Power Pivot measures, Pivot outputs, CUBE formulas, or Power Query results. The four dashboard pages already reference these cells/ranges. | P88: LINKING NOTE Replace the blank cells on this sheet with your Power Pivot measures, Pivot outputs, CUBE formulas, or Power Query results. The four dashboard pages already reference these cells/ranges. | Q88: LINKING NOTE Replace the blank cells on this sheet with your Power Pivot measures, Pivot outputs, CUBE formulas, or Power Query results. The four dashboard pages already reference these cells/ranges. | R88: LINKING NOTE Replace the blank cells on this sheet with your Power Pivot measures, Pivot outputs, CUBE formulas, or Power Query results. The four dashboard pages already reference these cells/ranges. | S88: LINKING NOTE Replace the blank cells on this sheet with your Power Pivot measures, Pivot outputs, CUBE formulas, or Power Query results. The four dashboard pages already reference these cells/ranges.
...

Sheet Sheet1
A1: P01 —Sales by Year
A2: Row Labels | B2: Total Sales | C2: Total Freight | D2: Total Order Value | E2: Total Orders | F2: Average Order Value
A3: 2016 | B3: 49785.92 | C3: 7397.29 | D3: 57183.21 | E3: 329 | F3: 173.80915
A4: 2017 | B4: 6155807 | C4: 986865.45 | D4: 7142672.4 | E4: 45101 | F4: 158.3706
A5: 2018 | B5: 7386050.8 | C5: 1257646.8 | D5: 8643697.6 | E5: 54011 | F5: 160.03587
A6: Grand Total | B6: 13591644 | C6: 2251909.5 | D6: 15843553 | E6: 99441 | F6: 159.32617
A10: P02 —Sales by Year & Month
A11: Row Labels | B11: Month Number | C11: Month | D11: Total Sales | E11: Total Freight | F11: Total Order Value | G11: Total Orders | H11: Average Order Value
A12: 2016 | B12: 9 | C12: September | D12: 267.36 | E12: 87.39 | F12: 354.75 | G12: 4 | H12: 88.6875
A13: 2016 | B13: 10 | C13: October | D13: 49507.66 | E13: 7301.18 | F13: 56808.84 | G13: 324 | H13: 175.33593
A14: 2016 | B14: 12 | C14: December | D14: 10.9 | E14: 8.72 | F14: 19.62 | G14: 1 | H14: 19.62
A15: 2017 | B15: 1 | C15: January | D15: 120312.87 | E15: 16875.62 | F15: 137188.49 | G15: 800 | H15: 171.48561
A16: 2017 | B16: 2 | C16: February | D16: 247303.02 | E16: 38977.6 | F16: 286280.62 | G16: 1780 | H16: 160.83181
A17: 2017 | B17: 3 | C17: March | D17: 374344.3 | E17: 57704.29 | F17: 432048.59 | G17: 2682 | H17: 161.09194
A18: 2017 | B18: 4 | C18: April | D18: 359927.23 | E18: 52495.01 | F18: 412422.24 | G18: 2404 | H18: 171.55667
A19: 2017 | B19: 5 | C19: May | D19: 506071.14 | E19: 80119.81 | F19: 586190.95 | G19: 3700 | H19: 158.42999
A20: 2017 | B20: 6 | C20: June | D20: 433038.6 | E20: 69924.44 | F20: 502963.04 | G20: 3245 | H20: 154.99631
A21: 2017 | B21: 7 | C21: July | D21: 498031.48 | E21: 86940.14 | F21: 584971.62 | G21: 4026 | H21: 145.29846
A22: 2017 | B22: 8 | C22: August | D22: 573971.68 | E22: 94232.92 | F22: 668204.6 | G22: 4331 | H22: 154.28414
A23: 2017 | B23: 9 | C23: September | D23: 624401.69 | E23: 95997.22 | F23: 720398.91 | G23: 4285 | H23: 168.1211
... A35: 2018 | B35: 9 | C35: September | D35: 145 | E35: 21.46 | F35: 166.46 | G35: 16 | H35: 10.40375
A36: 2018 | B36: 10 | C36: October | G36: 4
A40: P03 — Sales by Product Category
A41: Row Labels | B41: Total Sales
A42: health_beauty | B42: 1258681.3
A43: watches_gifts | B43: 1205005.7
A44: bed_bath_table | B44: 1036988.7
A45: sports_leisure | B45: 988048.97
A46: computers_accessories | B46: 911954.32
A47: furniture_decor | B47: 729762.49
A48: cool_stuff | B48: 635290.85
A49: housewares | B49: 632248.66
A50: auto | B50: 592720.11
A51: garden_tools | B51: 485256.46
A52: toys | B52: 483946.6
A53: baby | B53: 411764.89
... A56: office_furniture | B56: 273960.7
A57: Note | B57: Top 15 categories shown for readability; source remains live to the Data Model.
A59: P04 — Sales by Customer State | I59: Customer State
A60: Row Labels | B60: Total Sales | I60: Row Labels | J60: Total Customers
...

Sheet Sheet2
B3: Row Labels | C3: Total Sales
B4: AC | C4: 267
B5: AM | C5: 1177
B6: BA | C6: 286903.56
B7: CE | C7: 20240.64
B8: DF | C8: 89881.68
B9: ES | C9: 47779.51
B10: GO | C10: 66399.21
B11: MA | C11: 36408.95
B12: MG | C12: 1031107.2
B13: MS | C13: 8551.69
B14: MT | C14: 17070.72
B15: PB | C15: 17095
... B27: Grand Total | C27: 13591644

Sheet 01_Executive
A1: olist | B1: olist | C1: 1. Executive Overview | D1: 1. Executive Overview | E1: 1. Executive Overview | F1: 1. Executive Overview | G1: 1. Executive Overview | H1: 1. Executive Overview | I1: 1. Executive Overview | J1: 1. Executive Overview | K1: 1. Executive Overview
A2: olist | B2: olist | C2: Overview | D2: Overview | E2: A complete view of Olist's performance and business highlights. | F2: Sales & Customers | G2: Sales & Customers | H2: A complete view of Olist's performance and business highlights. | I2: Products & Sellers | J2: Products & Sellers | K2: A complete view of Olist's performance and business highlights.
A4: Year | B4: Year | E4: Month | F4: Month | G4: State | H4: State | K4: Payment / Status | L4: Payment / Status | M4: Payment / Status | N4: Payment / Status
A5: All | B5: All | E5: All | F5: All | G5: All | H5: All | Q5: 1
Q6: 2
A7: Total Sales | B7: Total Sales | D7: Total Orders | E7: Total Orders | G7: Total Customers | H7: Total Customers | J7: Average Order Value | K7: Average Order Value | Q7: 3
A8: =Sheet1!B6 -> 13591644 | D8: =Sheet1!E6 -> 99441 | G8: =Dashboard_Data!B9 -> 99441 | J8: =Sheet1!F6 -> 159.32617 | Q8: 4
A11: Average Review Score | B11: Average Review Score | D11: Average Delivery Days | E11: Average Delivery Days | G11: On-Time Delivery | H11: On-Time Delivery | J11: Late Orders | K11: Late Orders
A12: =Dashboard_Data!B12 -> 4.0864206 | D12: =Dashboard_Data!B13 -> 12.497336 | G12: =Dashboard_Data!B14 -> 0.93226295 | J12: =Dashboard_Data!B15 -> 6535
A14: Sales, Freight and Order Value by Year | H14: Orders Trend by Month
A28: Payment Methods | F28: Delivery Status | K28: Review Score Distribution

Sheet 02_Sales_Customers
A1: olist | B1: olist | C1: 2. Sales & Customers | D1: 2. Sales & Customers | E1: 2. Sales & Customers | F1: 2. Sales & Customers | G1: 2. Sales & Customers | H1: 2. Sales & Customers | I1: 2. Sales & Customers | J1: 2. Sales & Customers | K1: 2. Sales & Customers
A2: olist | B2: olist
A4: Year | B4: Year | E4: Month | F4: Month | G4: State | H4: State | I4: Category | J4: Category | K4: Payment / Status | L4: Payment / Status | M4: Payment / Status | N4: Payment / Status
A5: All | B5: All | C5: All | D5: All | E5: All | F5: All | G5: All | H5: All | I5: All | J5: All | K5: All | L5: All | M5: All | N5: All
A7: Total Sales | B7: Total Sales | D7: Total Orders | E7: Total Orders | G7: Total Customers | H7: Total Customers | J7: Average Order Value | K7: Average Order Value
A8: =Dashboard_Data!B6 -> 13591644 | D8: =Dashboard_Data!B7 -> 99441 | G8: =Dashboard_Data!B9 -> 99441 | J8: =Dashboard_Data!B8 -> 159.32617
A15: Sales by Year | F15: Monthly Sales Trend | K15: Customer Growth
A29: Customers by State | H29: Top States by Sales

Sheet 03_Products_Sellers
A1: olist | B1: olist | C1: 3. Products & Sellers | D1: 3. Products & Sellers | E1: 3. Products & Sellers | F1: 3. Products & Sellers | G1: 3. Products & Sellers | H1: 3. Products & Sellers | I1: 3. Products & Sellers | J1: 3. Products & Sellers | K1: 3. Products & Sellers | L1: Data Period | M1: Data Period | N1: Data Period
A2: olist | B2: olist | C2: Overview | D2: Overview | E2: Analyze product categories, top products, sellers and payment behavior. | F2: Sales & Customers | G2: Sales & Customers | H2: Analyze product categories, top products, sellers and payment behavior. | I2: Products & Sellers | J2: Products & Sellers | K2: Analyze product categories, top products, sellers and payment behavior. | L2: Delivery & CX | M2: Delivery & CX | N2: All / link later
A4: Year | B4: Year | C4: Quarter | D4: Quarter | E4: Month | F4: Month | G4: State | H4: State | I4: Category | J4: Category | K4: Payment / Status | L4: Payment / Status | M4: Payment / Status | N4: Payment / Status
A5: All | B5: All | C5: All | D5: All | E5: All | F5: All | G5: All | H5: All | I5: All | J5: All | K5: All | L5: All | M5: All | N5: All
A7: Total Products | B7: Total Products | G7: Total Sellers | H7: Total Sellers | J7: Total Sales | K7: Total Sales
A8: =Dashboard_Data!B10 -> 112650 | G8: =Dashboard_Data!B11 -> 3095 | J8: =Dashboard_Data!B6 -> 13591644
A15: Sales by Product Category (Top 10) | F15: Top 10 Products by Sales | K15: Top 10 Sellers by Sales
A29: Payment Type by Value | F29: Payment Installments | K29: Insight box — use this area for the top category, top product and top seller after connecting your data. | L29: Insight box — use this area for the top category, top product and top seller after connecting your data. | M29: Insight box — use this area for the top category, top product and top seller after connecting your data. | N29: Insight box — use this area for the top category, top product and top seller after connecting your data.
K30: Insight box — use this area for the top category, top product and top seller after connecting your data. | L30: Insight box — use this area for the top category, top product and top seller after connecting your data. | M30: Insight box — use this area for the top category, top product and top seller after connecting your data. | N30: Insight box — use this area for the top category, top product and top seller after connecting your data.
K31: Insight box — use this area for the top category, top product and top seller after connecting your data. | L31: Insight box — use this area for the top category, top product and top seller after connecting your data. | M31: Insight box — use this area for the top category, top product and top seller after connecting your data. | N31: Insight box — use this area for the top category, top product and top seller after connecting your data.
K32: Insight box — use this area for the top category, top product and top seller after connecting your data. | L32: Insight box — use this area for the top category, top product and top seller after connecting your data. | M32: Insight box — use this area for the top category, top product and top seller after connecting your data. | N32: Insight box — use this area for the top category, top product and top seller after connecting your data.
K33: Insight box — use this area for the top category, top product and top seller after connecting your data. | L33: Insight box — use this area for the top category, top product and top seller after connecting your data. | M33: Insight box — use this area for the top category, top product and top seller after connecting your data. | N33: Insight box — use this area for the top category, top product and top seller after connecting your data.
K34: Insight box — use this area for the top category, top product and top seller after connecting your data. | L34: Insight box — use this area for the top category, top product and top seller after connecting your data. | M34: Insight box — use this area for the top category, top product and top seller after connecting your data. | N34: Insight box — use this area for the top category, top product and top seller after connecting your data.
K35: Insight box — use this area for the top category, top product and top seller after connecting your data. | L35: Insight box — use this area for the top category, top product and top seller after connecting your data. | M35: Insight box — use this area for the top category, top product and top seller after connecting your data. | N35: Insight box — use this area for the top category, top product and top seller after connecting your data.
K36: Insight box — use this area for the top category, top product and top seller after connecting your data. | L36: Insight box — use this area for the top category, top product and top seller after connecting your data. | M36: Insight box — use this area for the top category, top product and top seller after connecting your data. | N36: Insight box — use this area for the top category, top product and top seller after connecting your data.
K37: Insight box — use this area for the top category, top product and top seller after connecting your data. | L37: Insight box — use this area for the top category, top product and top seller after connecting your data. | M37: Insight box — use this area for the top category, top product and top seller after connecting your data. | N37: Insight box — use this area for the top category, top product and top seller after connecting your data.
K38: Insight box — use this area for the top category, top product and top seller after connecting your data. | L38: Insight box — use this area for the top category, top product and top seller after connecting your data. | M38: Insight box — use this area for the top category, top product and top seller after connecting your data. | N38: Insight box — use this area for the top category, top product and top seller after connecting your data.
K39: Insight box — use this area for the top category, top product and top seller after connecting your data. | L39: Insight box — use this area for the top category, top product and top seller after connecting your data. | M39: Insight box — use this area for the top category, top product and top seller after connecting your data. | N39: Insight box — use this area for the top category, top product and top seller after connecting your data.

Sheet 04_Delivery_CX
A1: olist | B1: olist | C1: 4. Delivery & Customer Experience | D1: 4. Delivery & Customer Experience | E1: 4. Delivery & Customer Experience | F1: 4. Delivery & Customer Experience | G1: 4. Delivery & Customer Experience | H1: 4. Delivery & Customer Experience | I1: 4. Delivery & Customer Experience | J1: 4. Delivery & Customer Experience | K1: 4. Delivery & Customer Experience | L1: Data Period | M1: Data Period | N1: Data Period
A2: olist | B2: olist | C2: Overview | D2: Overview | E2: Track delivery performance and customer satisfaction. | F2: Sales & Customers | G2: Sales & Customers | H2: Track delivery performance and customer satisfaction. | I2: Products & Sellers | J2: Products & Sellers | K2: Track delivery performance and customer satisfaction. | L2: Delivery & CX | M2: Delivery & CX | N2: All / link later
A4: Year | B4: Year | C4: Quarter | D4: Quarter | E4: Month | F4: Month | G4: State | H4: State | I4: Category | J4: Category | K4: Payment / Status | L4: Payment / Status | M4: Payment / Status | N4: Payment / Status
A5: All | B5: All | C5: All | D5: All | E5: All | F5: All | G5: All | H5: All | I5: All | J5: All | K5: All | L5: All | M5: All | N5: All
A7: On-Time Delivery | B7: On-Time Delivery | D7: Late Orders | E7: Late Orders | G7: Not Delivered | H7: Not Delivered | J7: Average Review Score | K7: Average Review Score | M7: Average Delivery Days | N7: Average Delivery Days
A8: =Dashboard_Data!B15 -> 6535 | D8: =Dashboard_Data!B16 -> 2965 | G8: =Dashboard_Data!B17 -> 0 | J8: =Dashboard_Data!B13 -> 12.497336 | M8: =Dashboard_Data!B14 -> 0.93226295
A15: Delivery Status | F15: Delivery Performance by Year | K15: Average Delivery Days by Year
A29: Review Score Distribution | F29: Review Trend | K29: Customer experience insight area — connect delivery performance to review behavior after the data is connected. | L29: Customer experience insight area — connect delivery performance to review behavior after the data is connected. | M29: Customer experience insight area — connect delivery performance to review behavior after the data is connected. | N29: Customer experience insight area — connect delivery performance to review behavior after the data is connected.
K30: Customer experience insight area — connect delivery performance to review behavior after the data is connected. | L30: Customer experience insight area — connect delivery performance to review behavior after the data is connected. | M30: Customer experience insight area — connect delivery performance to review behavior after the data is connected. | N30: Customer experience insight area — connect delivery performance to review behavior after the data is connected.
K31: Customer experience insight area — connect delivery performance to review behavior after the data is connected. | L31: Customer experience insight area — connect delivery performance to review behavior after the data is connected. | M31: Customer experience insight area — connect delivery performance to review behavior after the data is connected. | N31: Customer experience insight area — connect delivery performance to review behavior after the data is connected.
K32: Customer experience insight area — connect delivery performance to review behavior after the data is connected. | L32: Customer experience insight area — connect delivery performance to review behavior after the data is connected. | M32: Customer experience insight area — connect delivery performance to review behavior after the data is connected. | N32: Customer experience insight area — connect delivery performance to review behavior after the data is connected.
K33: Customer experience insight area — connect delivery performance to review behavior after the data is connected. | L33: Customer experience insight area — connect delivery performance to review behavior after the data is connected. | M33: Customer experience insight area — connect delivery performance to review behavior after the data is connected. | N33: Customer experience insight area — connect delivery performance to review behavior after the data is connected.
K34: Customer experience insight area — connect delivery performance to review behavior after the data is connected. | L34: Customer experience insight area — connect delivery performance to review behavior after the data is connected. | M34: Customer experience insight area — connect delivery performance to review behavior after the data is connected. | N34: Customer experience insight area — connect delivery performance to review behavior after the data is connected.
K35: Customer experience insight area — connect delivery performance to review behavior after the data is connected. | L35: Customer experience insight area — connect delivery performance to review behavior after the data is connected. | M35: Customer experience insight area — connect delivery performance to review behavior after the data is connected. | N35: Customer experience insight area — connect delivery performance to review behavior after the data is connected.
K36: Customer experience insight area — connect delivery performance to review behavior after the data is connected. | L36: Customer experience insight area — connect delivery performance to review behavior after the data is connected. | M36: Customer experience insight area — connect delivery performance to review behavior after the data is connected. | N36: Customer experience insight area — connect delivery performance to review behavior after the data is connected.
K37: Customer experience insight area — connect delivery performance to review behavior after the data is connected. | L37: Customer experience insight area — connect delivery performance to review behavior after the data is connected. | M37: Customer experience insight area — connect delivery performance to review behavior after the data is connected. | N37: Customer experience insight area — connect delivery performance to review behavior after the data is connected.
K38: Customer experience insight area — connect delivery performance to review behavior after the data is connected. | L38: Customer experience insight area — connect delivery performance to review behavior after the data is connected. | M38: Customer experience insight area — connect delivery performance to review behavior after the data is connected. | N38: Customer experience insight area — connect delivery performance to review behavior after the data is connected.
K39: Customer experience insight area — connect delivery performance to review behavior after the data is connected. | L39: Customer experience insight area — connect delivery performance to review behavior after the data is connected. | M39: Customer experience insight area — connect delivery performance to review behavior after the data is connected. | N39: Customer experience insight area — connect delivery performance to review behavior after the data is connected.

Sheet Field_Map
A1: Olist Dashboard Template — Field Map | B1: Olist Dashboard Template — Field Map | C1: Olist Dashboard Template — Field Map | D1: Olist Dashboard Template — Field Map | E1: Olist Dashboard Template — Field Map | F1: Olist Dashboard Template — Field Map
A2: Olist Dashboard Template — Field Map | B2: Olist Dashboard Template — Field Map | C2: Olist Dashboard Template — Field Map | D2: Olist Dashboard Template — Field Map | E2: Olist Dashboard Template — Field Map | F2: Olist Dashboard Template — Field Map
A3: Use this map when connecting your source tables later. | B3: Use this map when connecting your source tables later. | C3: Use this map when connecting your source tables later. | D3: Use this map when connecting your source tables later. | E3: Use this map when connecting your source tables later. | F3: Use this map when connecting your source tables later.
A5: Dashboard Area | B5: Source Table | C5: Required Field(s) | D5: Metric / Output | E5: Grain | F5: Notes
A6: Sales | B6: Order Items | C6: price, freight_value | D6: Sales / Freight / Order Value | E6: Item | F6: price = sales
A7: Orders | B7: Orders | C7: order_id | D7: Total Orders | E7: Order | F7: Distinct order_id
A8: Customers | B8: Customers | C8: customer_unique_id | D8: Total Customers | E8: Customer | F8: Distinct customer_unique_id
A9: Customer Geography | B9: Customers | C9: customer_state | D9: Customers by State | E9: Customer | F9: State dimension
A10: Products | B10: Products | C10: product_id, category | D10: Products / Categories | E10: Product | F10: Distinct product_id
A11: Sellers | B11: Sellers | C11: seller_id | D11: Total Sellers | E11: Seller | F11: Distinct seller_id
A12: Payments | B12: Order Payments | C12: payment_type, payment_value, payment_installments | D12: Payment Mix / Installments | E12: Payment | F12: Use payment_value
A13: Reviews | B13: Order Reviews | C13: review_id, review_score | D13: Review Distribution | E13: Review | F13: Count review_id
... A19: Top Sellers | B19: Order Items | C19: seller_id, price | D19: Top Sellers | E19: Item | F19: Rank by sales
